PS C:\Users\Madhava Sharma\Desktop\-python> django-admin startproject mapp
PS C:\Users\Madhava Sharma\Desktop\-python> cd mapp
PS C:\Users\Madhava Sharma\Desktop\-python\mapp> python manage.py startapp mapp
CommandError: 'mapp' conflicts with the name of an existing Python module and cannot be used as an app name. Please try another name.
PS C:\Users\Madhava Sharma\Desktop\-python\mapp> python manage.py startapp madapp
PS C:\Users\Madhava Sharma\Desktop\-python\mapp> python manage.py make migrations
Traceback (most recent call last):
  File "C:\Users\Madhava Sharma\AppData\Local\Programs\Python\Python311\Lib\site-packages\django\db\backends\mysql\base.py", line 15, in <module>
    import MySQLdb as Database
ModuleNotFoundError: No module named 'MySQLdb'

The above exception was the direct cause of the following exception:

Traceback (most recent call last):
  File "C:\Users\Madhava Sharma\Desktop\-python\mapp\manage.py", line 22, in <module>
    main()
  File "C:\Users\Madhava Sharma\Desktop\-python\mapp\manage.py", line 18, in main
    execute_from_command_line(sys.argv)
  File "C:\Users\Madhava Sharma\AppData\Local\Programs\Python\Python311\Lib\site-packages\django\core\management\__init__.py", line 446, in execute_from_command_line
    utility.execute()
  File "C:\Users\Madhava Sharma\AppData\Local\Programs\Python\Python311\Lib\site-packages\django\core\management\__init__.py", line 420, in execute
    django.setup()
  File "C:\Users\Madhava Sharma\AppData\Local\Programs\Python\Python311\Lib\site-packages\django\__init__.py", line 24, in setup
    apps.populate(settings.INSTALLED_APPS)
  File "C:\Users\Madhava Sharma\AppData\Local\Programs\Python\Python311\Lib\site-packages\django\apps\registry.py", line 
116, in populate
    app_config.import_models()
  File "C:\Users\Madhava Sharma\AppData\Local\Programs\Python\Python311\Lib\site-packages\django\apps\config.py", line 269, in import_models
    self.models_module = import_module(models_module_name)
                         ^^^^^^^^^^^^^^^^^^^^^^^^^^^^^^^^^
  File "C:\Users\Madhava Sharma\AppData\Local\Programs\Python\Python311\Lib\importlib\__init__.py", line 126, in import_module
    return _bootstrap._gcd_import(name[level:], package, level)
           ^^^^^^^^^^^^^^^^^^^^^^^^^^^^^^^^^^^^^^^^^^^^^^^^^^^^
  File "<frozen importlib._bootstrap>", line 1206, in _gcd_import
  File "<frozen importlib._bootstrap>", line 1178, in _find_and_load
  File "<frozen importlib._bootstrap>", line 1149, in _find_and_load_unlocked
  File "<frozen importlib._bootstrap>", line 690, in _load_unlocked
  File "<frozen importlib._bootstrap_external>", line 940, in exec_module
  File "<frozen importlib._bootstrap>", line 241, in _call_with_frames_removed
  File "C:\Users\Madhava Sharma\AppData\Local\Programs\Python\Python311\Lib\site-packages\django\contrib\auth\models.py", line 3, in <module>
    from django.contrib.auth.base_user import AbstractBaseUser, BaseUserManager
  File "C:\Users\Madhava Sharma\AppData\Local\Programs\Python\Python311\Lib\site-packages\django\contrib\auth\base_user.py", line 49, in <module>
    class AbstractBaseUser(models.Model):
  File "C:\Users\Madhava Sharma\AppData\Local\Programs\Python\Python311\Lib\site-packages\django\db\models\base.py", line 141, in __new__
    new_class.add_to_class("_meta", Options(meta, app_label))
  File "C:\Users\Madhava Sharma\AppData\Local\Programs\Python\Python311\Lib\site-packages\django\db\models\base.py", line 369, in add_to_class
    value.contribute_to_class(cls, name)
  File "C:\Users\Madhava Sharma\AppData\Local\Programs\Python\Python311\Lib\site-packages\django\db\models\options.py", line 231, in contribute_to_class
    self.db_table, connection.ops.max_name_length()
                   ^^^^^^^^^^^^^^
  File "C:\Users\Madhava Sharma\AppData\Local\Programs\Python\Python311\Lib\site-packages\django\utils\connection.py", line 15, in __getattr__
    return getattr(self._connections[self._alias], item)
                   ~~~~~~~~~~~~~~~~~^^^^^^^^^^^^^
  File "C:\Users\Madhava Sharma\AppData\Local\Programs\Python\Python311\Lib\site-packages\django\utils\connection.py", line 62, in __getitem__
    conn = self.create_connection(alias)
           ^^^^^^^^^^^^^^^^^^^^^^^^^^^^^
  File "C:\Users\Madhava Sharma\AppData\Local\Programs\Python\Python311\Lib\site-packages\django\db\utils.py", line 193, 
in create_connection
    backend = load_backend(db["ENGINE"])
              ^^^^^^^^^^^^^^^^^^^^^^^^^^
  File "C:\Users\Madhava Sharma\AppData\Local\Programs\Python\Python311\Lib\site-packages\django\db\utils.py", line 113, 
    return import_module("%s.base" % backend_name)
           ^^^^^^^^^^^^^^^^^^^^^^^^^^^^^^^^^^^^^^^
  File "C:\Users\Madhava Sharma\AppData\Local\Programs\Python\Python311\Lib\importlib\__init__.py", line 126, in import_module
    return _bootstrap._gcd_import(name[level:], package, level)
           ^^^^^^^^^^^^^^^^^^^^^^^^^^^^^^^^^^^^^^^^^^^^^^^^^^^^
  File "C:\Users\Madhava Sharma\AppData\Local\Programs\Python\Python311\Lib\site-packages\django\db\backends\mysql\base.py", line 17, in <module>
    raise ImproperlyConfigured(
django.core.exceptions.ImproperlyConfigured: Error loading MySQLdb module.
Did you install mysqlclient?
PS C:\Users\Madhava Sharma\Desktop\-python\mapp> python manage.py make migrations
Traceback (most recent call last):
  File "C:\Users\Madhava Sharma\Desktop\-python\mapp\manage.py", line 22, in <module>
    main()
  File "C:\Users\Madhava Sharma\Desktop\-python\mapp\manage.py", line 18, in main
    execute_from_command_line(sys.argv)
  File "C:\Users\Madhava Sharma\AppData\Local\Programs\Python\Python311\Lib\site-packages\django\core\management\__init__.py", line 446, in execute_from_command_line
    utility.execute()
  File "C:\Users\Madhava Sharma\AppData\Local\Programs\Python\Python311\Lib\site-packages\django\core\management\__init__.py", line 420, in execute
    django.setup()
  File "C:\Users\Madhava Sharma\AppData\Local\Programs\Python\Python311\Lib\site-packages\django\__init__.py", line 24, in setup
    apps.populate(settings.INSTALLED_APPS)
  File "C:\Users\Madhava Sharma\AppData\Local\Programs\Python\Python311\Lib\site-packages\django\apps\registry.py", line 
116, in populate
    app_config.import_models()
  File "C:\Users\Madhava Sharma\AppData\Local\Programs\Python\Python311\Lib\site-packages\django\apps\config.py", line 269, in import_models
    self.models_module = import_module(models_module_name)
                         ^^^^^^^^^^^^^^^^^^^^^^^^^^^^^^^^^
  File "C:\Users\Madhava Sharma\AppData\Local\Programs\Python\Python311\Lib\importlib\__init__.py", line 126, in import_module
    return _bootstrap._gcd_import(name[level:], package, level)
           ^^^^^^^^^^^^^^^^^^^^^^^^^^^^^^^^^^^^^^^^^^^^^^^^^^^^
  File "<frozen importlib._bootstrap>", line 1178, in _find_and_load
  File "<frozen importlib._bootstrap>", line 1149, in _find_and_load_unlocked
  File "<frozen importlib._bootstrap>", line 690, in _load_unlocked
  File "<frozen importlib._bootstrap_external>", line 940, in exec_module
  File "<frozen importlib._bootstrap>", line 241, in _call_with_frames_removed
  File "C:\Users\Madhava Sharma\Desktop\-python\mapp\madapp\models.py", line 4, in <module>
    class empdtls(models.Model):
  File "C:\Users\Madhava Sharma\Desktop\-python\mapp\madapp\models.py", line 5, in empdtls
    empid=models.IntergerField()
          ^^^^^^^^^^^^^^^^^^^^
AttributeError: module 'django.db.models' has no attribute 'IntergerField'. Did you mean: 'IntegerField'?
PS C:\Users\Madhava Sharma\Desktop\-python\mapp> python manage.py make migrations
Traceback (most recent call last):
  File "C:\Users\Madhava Sharma\Desktop\-python\mapp\manage.py", line 22, in <module>
    main()
  File "C:\Users\Madhava Sharma\Desktop\-python\mapp\manage.py", line 18, in main
    execute_from_command_line(sys.argv)
  File "C:\Users\Madhava Sharma\AppData\Local\Programs\Python\Python311\Lib\site-packages\django\core\management\__init__.py", line 446, in execute_from_command_line
    utility.execute()
  File "C:\Users\Madhava Sharma\AppData\Local\Programs\Python\Python311\Lib\site-packages\django\core\management\__init__.py", line 420, in execute
    django.setup()
  File "C:\Users\Madhava Sharma\AppData\Local\Programs\Python\Python311\Lib\site-packages\django\__init__.py", line 24, in setup
    apps.populate(settings.INSTALLED_APPS)
  File "C:\Users\Madhava Sharma\AppData\Local\Programs\Python\Python311\Lib\site-packages\django\apps\registry.py", line 
116, in populate
    app_config.import_models()
  File "C:\Users\Madhava Sharma\AppData\Local\Programs\Python\Python311\Lib\site-packages\django\apps\config.py", line 269, in import_models
    self.models_module = import_module(models_module_name)
                         ^^^^^^^^^^^^^^^^^^^^^^^^^^^^^^^^^
  File "C:\Users\Madhava Sharma\AppData\Local\Programs\Python\Python311\Lib\importlib\__init__.py", line 126, in import_module
    return _bootstrap._gcd_import(name[level:], package, level)
           ^^^^^^^^^^^^^^^^^^^^^^^^^^^^^^^^^^^^^^^^^^^^^^^^^^^^
  File "<frozen importlib._bootstrap>", line 1178, in _find_and_load
  File "<frozen importlib._bootstrap>", line 1149, in _find_and_load_unlocked
  File "<frozen importlib._bootstrap>", line 690, in _load_unlocked
  File "<frozen importlib._bootstrap_external>", line 940, in exec_module
  File "<frozen importlib._bootstrap>", line 241, in _call_with_frames_removed
  File "C:\Users\Madhava Sharma\Desktop\-python\mapp\madapp\models.py", line 4, in <module>
    class empdtls(models.Model):
  File "C:\Users\Madhava Sharma\Desktop\-python\mapp\madapp\models.py", line 5, in empdtls
    empid=models.IntergerField()
          ^^^^^^^^^^^^^^^^^^^^
AttributeError: module 'django.db.models' has no attribute 'IntergerField'. Did you mean: 'IntegerField'?
PS C:\Users\Madhava Sharma\Desktop\-python\mapp> python manage.py make migrations
Traceback (most recent call last):
  File "C:\Users\Madhava Sharma\Desktop\-python\mapp\manage.py", line 22, in <module>
    main()
  File "C:\Users\Madhava Sharma\Desktop\-python\mapp\manage.py", line 18, in main
    execute_from_command_line(sys.argv)
  File "C:\Users\Madhava Sharma\AppData\Local\Programs\Python\Python311\Lib\site-packages\django\core\management\__init__.py", line 446, in execute_from_command_line
    utility.execute()
  File "C:\Users\Madhava Sharma\AppData\Local\Programs\Python\Python311\Lib\site-packages\django\core\management\__init__.py", line 420, in execute
    django.setup()
  File "C:\Users\Madhava Sharma\AppData\Local\Programs\Python\Python311\Lib\site-packages\django\__init__.py", line 24, in setup
    apps.populate(settings.INSTALLED_APPS)
  File "C:\Users\Madhava Sharma\AppData\Local\Programs\Python\Python311\Lib\site-packages\django\apps\registry.py", line 
116, in populate
    app_config.import_models()
  File "C:\Users\Madhava Sharma\AppData\Local\Programs\Python\Python311\Lib\site-packages\django\apps\config.py", line 269, in import_models
    self.models_module = import_module(models_module_name)
                         ^^^^^^^^^^^^^^^^^^^^^^^^^^^^^^^^^
  File "C:\Users\Madhava Sharma\AppData\Local\Programs\Python\Python311\Lib\importlib\__init__.py", line 126, in import_module
    return _bootstrap._gcd_import(name[level:], package, level)
           ^^^^^^^^^^^^^^^^^^^^^^^^^^^^^^^^^^^^^^^^^^^^^^^^^^^^
  File "<frozen importlib._bootstrap>", line 1178, in _find_and_load
  File "<frozen importlib._bootstrap>", line 1149, in _find_and_load_unlocked
  File "<frozen importlib._bootstrap_external>", line 940, in exec_module
  File "<frozen importlib._bootstrap>", line 241, in _call_with_frames_removed
    class empdtls(models.Model):
  File "C:\Users\Madhava Sharma\Desktop\-python\mapp\madapp\models.py", line 5, in empdtls
    empid=models.BigIntergerField()
          ^^^^^^^^^^^^^^^^^^^^^^^
PS C:\Users\Madhava Sharma\Desktop\-python\mapp> python manage.py make migrations
Unknown command: 'make'
PS C:\Users\Madhava Sharma\Desktop\-python\mapp> python manage.py make migrate   
Type 'manage.py help' for usage.
PS C:\Users\Madhava Sharma\Desktop\-python\mapp> python manage.py makemigrations
Migrations for 'madapp':
  madapp\migrations\0001_initial.py
    - Create model empdtls
    - Create model log
PS C:\Users\Madhava Sharma\Desktop\-python\mapp> python manage.py make migrations
Unknown command: 'make'
Type 'manage.py help' for usage.
PS C:\Users\Madhava Sharma\Desktop\-python\mapp> python manage.py makemigrations 
No changes detected
PS C:\Users\Madhava Sharma\Desktop\-python\mapp> python manage.py migrate       
Operations to perform:
  Apply all migrations: admin, auth, contenttypes, madapp, sessions
Running migrations:
  Applying contenttypes.0001_initial... OK
  Applying auth.0001_initial... OK
  Applying admin.0001_initial... OK
  Applying admin.0002_logentry_remove_auto_add... OK
  Applying admin.0003_logentry_add_action_flag_choices... OK
  Applying contenttypes.0002_remove_content_type_name... OK
  Applying auth.0002_alter_permission_name_max_length... OK
  Applying auth.0004_alter_user_username_opts... OK
  Applying auth.0005_alter_user_last_login_null... OK
  Applying auth.0006_require_contenttypes_0002... OK
  Applying auth.0007_alter_validators_add_error_messages... OK
  Applying auth.0008_alter_user_username_max_length... OK
  Applying auth.0009_alter_user_last_name_max_length... OK
  Applying auth.0010_alter_group_name_max_length... OK
  Applying auth.0011_update_proxy_permissions... OK
  Applying auth.0012_alter_user_first_name_max_length... OK
  Applying madapp.0001_initial... OK
  Applying sessions.0001_initial... OK
PS C:\Users\Madhava Sharma\Desktop\-python\mapp> python manage.py runserver
Watching for file changes with StatReloader
Performing system checks...

System check identified no issues (0 silenced).
February 08, 2023 - 14:47:04
Django version 4.1.6, using settings 'mapp.settings'
Starting development server at http://127.0.0.1:8000/
Quit the server with CTRL-BREAK.
[08/Feb/2023 14:47:08] "GET / HTTP/1.1" 200 10681
[08/Feb/2023 14:47:09] "GET /static/admin/css/fonts.css HTTP/1.1" 200 423
[08/Feb/2023 14:47:09] "GET /static/admin/fonts/Roboto-Bold-webfont.woff HTTP/1.1" 200 86184
[08/Feb/2023 14:47:09] "GET /static/admin/fonts/Roboto-Light-webfont.woff HTTP/1.1" 200 85692
[08/Feb/2023 14:47:09] "GET /static/admin/fonts/Roboto-Regular-webfont.woff HTTP/1.1" 200 85876
Not Found: /favicon.ico
[08/Feb/2023 14:47:09] "GET /favicon.ico HTTP/1.1" 404 2108
Not Found: /adminp
[08/Feb/2023 14:47:21] "GET /adminp HTTP/1.1" 404 2093
C:\Users\Madhava Sharma\Desktop\-python\mapp\mapp\urls.py changed, reloading.
Watching for file changes with StatReloader
Performing system checks...

Exception in thread django-main-thread:
Traceback (most recent call last):
  File "C:\Users\Madhava Sharma\AppData\Local\Programs\Python\Python311\Lib\threading.py", line 1038, in _bootstrap_inner    self.run()
  File "C:\Users\Madhava Sharma\AppData\Local\Programs\Python\Python311\Lib\threading.py", line 975, in run
    self._target(*self._args, **self._kwargs)
  File "C:\Users\Madhava Sharma\AppData\Local\Programs\Python\Python311\Lib\site-packages\django\utils\autoreload.py", line 64, in wrapper
    fn(*args, **kwargs)
  File "C:\Users\Madhava Sharma\AppData\Local\Programs\Python\Python311\Lib\site-packages\django\core\management\commands\runserver.py", line 134, in inner_run
    self.check(display_num_errors=True)
  File "C:\Users\Madhava Sharma\AppData\Local\Programs\Python\Python311\Lib\site-packages\django\core\management\base.py", line 475, in check
    all_issues = checks.run_checks(
                 ^^^^^^^^^^^^^^^^^^
  File "C:\Users\Madhava Sharma\AppData\Local\Programs\Python\Python311\Lib\site-packages\django\core\checks\registry.py", line 88, in run_checks
    new_errors = check(app_configs=app_configs, databases=databases)
                 ^^^^^^^^^^^^^^^^^^^^^^^^^^^^^^^^^^^^^^^^^^^^^^^^^^^
  File "C:\Users\Madhava Sharma\AppData\Local\Programs\Python\Python311\Lib\site-packages\django\core\checks\urls.py", line 42, in check_url_namespaces_unique
    all_namespaces = _load_all_namespaces(resolver)
                     ^^^^^^^^^^^^^^^^^^^^^^^^^^^^^^
  File "C:\Users\Madhava Sharma\AppData\Local\Programs\Python\Python311\Lib\site-packages\django\core\checks\urls.py", line 61, in _load_all_namespaces
    url_patterns = getattr(resolver, "url_patterns", [])
                   ^^^^^^^^^^^^^^^^^^^^^^^^^^^^^^^^^^^^^
  File "C:\Users\Madhava Sharma\AppData\Local\Programs\Python\Python311\Lib\site-packages\django\utils\functional.py", line 57, in __get__
    res = instance.__dict__[self.name] = self.func(instance)
                                         ^^^^^^^^^^^^^^^^^^^
  File "C:\Users\Madhava Sharma\AppData\Local\Programs\Python\Python311\Lib\site-packages\django\urls\resolvers.py", line 715, in url_patterns
    patterns = getattr(self.urlconf_module, "urlpatterns", self.urlconf_module)
                       ^^^^^^^^^^^^^^^^^^^
  File "C:\Users\Madhava Sharma\AppData\Local\Programs\Python\Python311\Lib\site-packages\django\utils\functional.py", line 57, in __get__
    res = instance.__dict__[self.name] = self.func(instance)
                                         ^^^^^^^^^^^^^^^^^^^
  File "C:\Users\Madhava Sharma\AppData\Local\Programs\Python\Python311\Lib\site-packages\django\urls\resolvers.py", line 708, in urlconf_module
    return import_module(self.urlconf_name)
           ^^^^^^^^^^^^^^^^^^^^^^^^^^^^^^^^
  File "C:\Users\Madhava Sharma\AppData\Local\Programs\Python\Python311\Lib\importlib\__init__.py", line 126, in import_module
    return _bootstrap._gcd_import(name[level:], package, level)
           ^^^^^^^^^^^^^^^^^^^^^^^^^^^^^^^^^^^^^^^^^^^^^^^^^^^^
  File "<frozen importlib._bootstrap>", line 1206, in _gcd_import
  File "<frozen importlib._bootstrap>", line 1178, in _find_and_load
  File "<frozen importlib._bootstrap>", line 1149, in _find_and_load_unlocked
  File "<frozen importlib._bootstrap>", line 690, in _load_unlocked
  File "<frozen importlib._bootstrap_external>", line 936, in exec_module
  File "<frozen importlib._bootstrap_external>", line 1074, in get_code
  File "<frozen importlib._bootstrap_external>", line 1004, in source_to_code
  File "<frozen importlib._bootstrap>", line 241, in _call_with_frames_removed
  File "C:\Users\Madhava Sharma\Desktop\-python\mapp\mapp\urls.py", line 18
    from
         ^
SyntaxError: invalid syntax
C:\Users\Madhava Sharma\Desktop\-python\mapp\mapp\urls.py changed, reloading.
Watching for file changes with StatReloader
Performing system checks...

Exception in thread django-main-thread:
Traceback (most recent call last):
  File "C:\Users\Madhava Sharma\AppData\Local\Programs\Python\Python311\Lib\threading.py", line 1038, in _bootstrap_inner    self.run()
  File "C:\Users\Madhava Sharma\AppData\Local\Programs\Python\Python311\Lib\threading.py", line 975, in run
    self._target(*self._args, **self._kwargs)
  File "C:\Users\Madhava Sharma\AppData\Local\Programs\Python\Python311\Lib\site-packages\django\utils\autoreload.py", line 64, in wrapper
    fn(*args, **kwargs)
  File "C:\Users\Madhava Sharma\AppData\Local\Programs\Python\Python311\Lib\site-packages\django\core\management\commands\runserver.py", line 134, in inner_run
    self.check(display_num_errors=True)
  File "C:\Users\Madhava Sharma\AppData\Local\Programs\Python\Python311\Lib\site-packages\django\core\management\base.py", line 475, in check
    all_issues = checks.run_checks(
                 ^^^^^^^^^^^^^^^^^^
  File "C:\Users\Madhava Sharma\AppData\Local\Programs\Python\Python311\Lib\site-packages\django\core\checks\registry.py", line 88, in run_checks
    new_errors = check(app_configs=app_configs, databases=databases)
                 ^^^^^^^^^^^^^^^^^^^^^^^^^^^^^^^^^^^^^^^^^^^^^^^^^^^
  File "C:\Users\Madhava Sharma\AppData\Local\Programs\Python\Python311\Lib\site-packages\django\core\checks\urls.py", line 42, in check_url_namespaces_unique
    all_namespaces = _load_all_namespaces(resolver)
                     ^^^^^^^^^^^^^^^^^^^^^^^^^^^^^^
  File "C:\Users\Madhava Sharma\AppData\Local\Programs\Python\Python311\Lib\site-packages\django\core\checks\urls.py", line 61, in _load_all_namespaces
    url_patterns = getattr(resolver, "url_patterns", [])
                   ^^^^^^^^^^^^^^^^^^^^^^^^^^^^^^^^^^^^^
  File "C:\Users\Madhava Sharma\AppData\Local\Programs\Python\Python311\Lib\site-packages\django\utils\functional.py", line 57, in __get__
    res = instance.__dict__[self.name] = self.func(instance)
                                         ^^^^^^^^^^^^^^^^^^^
  File "C:\Users\Madhava Sharma\AppData\Local\Programs\Python\Python311\Lib\site-packages\django\urls\resolvers.py", line 715, in url_patterns
    patterns = getattr(self.urlconf_module, "urlpatterns", self.urlconf_module)
                       ^^^^^^^^^^^^^^^^^^^
  File "C:\Users\Madhava Sharma\AppData\Local\Programs\Python\Python311\Lib\site-packages\django\utils\functional.py", line 57, in __get__
    res = instance.__dict__[self.name] = self.func(instance)
                                         ^^^^^^^^^^^^^^^^^^^
  File "C:\Users\Madhava Sharma\AppData\Local\Programs\Python\Python311\Lib\site-packages\django\urls\resolvers.py", line 708, in urlconf_module
    return import_module(self.urlconf_name)
           ^^^^^^^^^^^^^^^^^^^^^^^^^^^^^^^^
  File "C:\Users\Madhava Sharma\AppData\Local\Programs\Python\Python311\Lib\importlib\__init__.py", line 126, in import_module
    return _bootstrap._gcd_import(name[level:], package, level)
           ^^^^^^^^^^^^^^^^^^^^^^^^^^^^^^^^^^^^^^^^^^^^^^^^^^^^
  File "<frozen importlib._bootstrap>", line 1206, in _gcd_import
  File "<frozen importlib._bootstrap>", line 1178, in _find_and_load
  File "<frozen importlib._bootstrap>", line 1149, in _find_and_load_unlocked
  File "<frozen importlib._bootstrap>", line 690, in _load_unlocked
  File "<frozen importlib._bootstrap_external>", line 936, in exec_module
  File "<frozen importlib._bootstrap_external>", line 1074, in get_code
  File "<frozen importlib._bootstrap_external>", line 1004, in source_to_code
  File "<frozen importlib._bootstrap>", line 241, in _call_with_frames_removed
  File "C:\Users\Madhava Sharma\Desktop\-python\mapp\mapp\urls.py", line 18
    from madapp
               ^
SyntaxError: invalid syntax
C:\Users\Madhava Sharma\Desktop\-python\mapp\mapp\urls.py changed, reloading.
Watching for file changes with StatReloader
Performing system checks...

Exception in thread django-main-thread:
Traceback (most recent call last):
  File "C:\Users\Madhava Sharma\AppData\Local\Programs\Python\Python311\Lib\threading.py", line 1038, in _bootstrap_inner    self.run()
  File "C:\Users\Madhava Sharma\AppData\Local\Programs\Python\Python311\Lib\threading.py", line 975, in run
    self._target(*self._args, **self._kwargs)
  File "C:\Users\Madhava Sharma\AppData\Local\Programs\Python\Python311\Lib\site-packages\django\utils\autoreload.py", line 64, in wrapper
    fn(*args, **kwargs)
  File "C:\Users\Madhava Sharma\AppData\Local\Programs\Python\Python311\Lib\site-packages\django\core\management\commands\runserver.py", line 134, in inner_run
    self.check(display_num_errors=True)
  File "C:\Users\Madhava Sharma\AppData\Local\Programs\Python\Python311\Lib\site-packages\django\core\management\base.py", line 475, in check
    all_issues = checks.run_checks(
                 ^^^^^^^^^^^^^^^^^^
  File "C:\Users\Madhava Sharma\AppData\Local\Programs\Python\Python311\Lib\site-packages\django\core\checks\registry.py", line 88, in run_checks
    new_errors = check(app_configs=app_configs, databases=databases)
                 ^^^^^^^^^^^^^^^^^^^^^^^^^^^^^^^^^^^^^^^^^^^^^^^^^^^
  File "C:\Users\Madhava Sharma\AppData\Local\Programs\Python\Python311\Lib\site-packages\django\core\checks\urls.py", line 42, in check_url_namespaces_unique
    all_namespaces = _load_all_namespaces(resolver)
                     ^^^^^^^^^^^^^^^^^^^^^^^^^^^^^^
  File "C:\Users\Madhava Sharma\AppData\Local\Programs\Python\Python311\Lib\site-packages\django\core\checks\urls.py", line 61, in _load_all_namespaces
    url_patterns = getattr(resolver, "url_patterns", [])
                   ^^^^^^^^^^^^^^^^^^^^^^^^^^^^^^^^^^^^^
  File "C:\Users\Madhava Sharma\AppData\Local\Programs\Python\Python311\Lib\site-packages\django\utils\functional.py", line 57, in __get__
    res = instance.__dict__[self.name] = self.func(instance)
                                         ^^^^^^^^^^^^^^^^^^^
  File "C:\Users\Madhava Sharma\AppData\Local\Programs\Python\Python311\Lib\site-packages\django\urls\resolvers.py", line 715, in url_patterns
    patterns = getattr(self.urlconf_module, "urlpatterns", self.urlconf_module)
                       ^^^^^^^^^^^^^^^^^^^
  File "C:\Users\Madhava Sharma\AppData\Local\Programs\Python\Python311\Lib\site-packages\django\utils\functional.py", line 57, in __get__
    res = instance.__dict__[self.name] = self.func(instance)
                                         ^^^^^^^^^^^^^^^^^^^
  File "C:\Users\Madhava Sharma\AppData\Local\Programs\Python\Python311\Lib\site-packages\django\urls\resolvers.py", line 708, in urlconf_module
    return import_module(self.urlconf_name)
           ^^^^^^^^^^^^^^^^^^^^^^^^^^^^^^^^
  File "C:\Users\Madhava Sharma\AppData\Local\Programs\Python\Python311\Lib\importlib\__init__.py", line 126, in import_module
    return _bootstrap._gcd_import(name[level:], package, level)
           ^^^^^^^^^^^^^^^^^^^^^^^^^^^^^^^^^^^^^^^^^^^^^^^^^^^^
  File "<frozen importlib._bootstrap>", line 1206, in _gcd_import
  File "<frozen importlib._bootstrap>", line 1178, in _find_and_load
  File "<frozen importlib._bootstrap>", line 1149, in _find_and_load_unlocked
  File "<frozen importlib._bootstrap>", line 690, in _load_unlocked
  File "<frozen importlib._bootstrap_external>", line 936, in exec_module
  File "<frozen importlib._bootstrap_external>", line 1074, in get_code
  File "<frozen importlib._bootstrap_external>", line 1004, in source_to_code
  File "<frozen importlib._bootstrap>", line 241, in _call_with_frames_removed
  File "C:\Users\Madhava Sharma\Desktop\-python\mapp\mapp\urls.py", line 18
    from madapp import
                       ^
SyntaxError: invalid syntax
C:\Users\Madhava Sharma\Desktop\-python\mapp\mapp\urls.py changed, reloading.
Watching for file changes with StatReloader
Performing system checks...

System check identified no issues (0 silenced).
February 08, 2023 - 14:55:47
Django version 4.1.6, using settings 'mapp.settings'
Starting development server at http://127.0.0.1:8000/
Quit the server with CTRL-BREAK.
C:\Users\Madhava Sharma\Desktop\-python\mapp\mapp\urls.py changed, reloading.
Watching for file changes with StatReloader
Performing system checks...

System check identified no issues (0 silenced).
February 08, 2023 - 14:56:09
Django version 4.1.6, using settings 'mapp.settings'
Starting development server at http://127.0.0.1:8000/
Quit the server with CTRL-BREAK.
C:\Users\Madhava Sharma\Desktop\-python\mapp\mapp\urls.py changed, reloading.
Watching for file changes with StatReloader
Performing system checks...

Exception in thread django-main-thread:
Traceback (most recent call last):
  File "C:\Users\Madhava Sharma\AppData\Local\Programs\Python\Python311\Lib\threading.py", line 1038, in _bootstrap_inner    self.run()
  File "C:\Users\Madhava Sharma\AppData\Local\Programs\Python\Python311\Lib\threading.py", line 975, in run
    self._target(*self._args, **self._kwargs)
  File "C:\Users\Madhava Sharma\AppData\Local\Programs\Python\Python311\Lib\site-packages\django\utils\autoreload.py", line 64, in wrapper
    fn(*args, **kwargs)
  File "C:\Users\Madhava Sharma\AppData\Local\Programs\Python\Python311\Lib\site-packages\django\core\management\commands\runserver.py", line 134, in inner_run
    self.check(display_num_errors=True)
  File "C:\Users\Madhava Sharma\AppData\Local\Programs\Python\Python311\Lib\site-packages\django\core\management\base.py", line 546, in check
    raise SystemCheckError(msg)
django.core.management.base.SystemCheckError: SystemCheckError: System check identified some issues:

ERRORS:
?: (urls.E004) Your URL pattern functools.partial(<function _path at 0x0000029F65CD36A0>, Pattern=<class 'django.urls.resolvers.RoutePattern'>) is invalid. Ensure that urlpatterns is a list of path() and/or re_path() instances.

System check identified 1 issue (0 silenced).
C:\Users\Madhava Sharma\Desktop\-python\mapp\mapp\urls.py changed, reloading.
Watching for file changes with StatReloader
Performing system checks...

Exception in thread django-main-thread:
Traceback (most recent call last):
  File "C:\Users\Madhava Sharma\AppData\Local\Programs\Python\Python311\Lib\threading.py", line 1038, in _bootstrap_inner    self.run()
  File "C:\Users\Madhava Sharma\AppData\Local\Programs\Python\Python311\Lib\threading.py", line 975, in run
    self._target(*self._args, **self._kwargs)
  File "C:\Users\Madhava Sharma\AppData\Local\Programs\Python\Python311\Lib\site-packages\django\utils\autoreload.py", line 64, in wrapper
    fn(*args, **kwargs)
  File "C:\Users\Madhava Sharma\AppData\Local\Programs\Python\Python311\Lib\site-packages\django\core\management\commands\runserver.py", line 134, in inner_run
    self.check(display_num_errors=True)
  File "C:\Users\Madhava Sharma\AppData\Local\Programs\Python\Python311\Lib\site-packages\django\core\management\base.py", line 475, in check
    all_issues = checks.run_checks(
                 ^^^^^^^^^^^^^^^^^^
  File "C:\Users\Madhava Sharma\AppData\Local\Programs\Python\Python311\Lib\site-packages\django\core\checks\registry.py", line 88, in run_checks
    new_errors = check(app_configs=app_configs, databases=databases)
                 ^^^^^^^^^^^^^^^^^^^^^^^^^^^^^^^^^^^^^^^^^^^^^^^^^^^
  File "C:\Users\Madhava Sharma\AppData\Local\Programs\Python\Python311\Lib\site-packages\django\core\checks\urls.py", line 42, in check_url_namespaces_unique
    all_namespaces = _load_all_namespaces(resolver)
                     ^^^^^^^^^^^^^^^^^^^^^^^^^^^^^^
  File "C:\Users\Madhava Sharma\AppData\Local\Programs\Python\Python311\Lib\site-packages\django\core\checks\urls.py", line 61, in _load_all_namespaces
    url_patterns = getattr(resolver, "url_patterns", [])
                   ^^^^^^^^^^^^^^^^^^^^^^^^^^^^^^^^^^^^^
  File "C:\Users\Madhava Sharma\AppData\Local\Programs\Python\Python311\Lib\site-packages\django\utils\functional.py", line 57, in __get__
    res = instance.__dict__[self.name] = self.func(instance)
                                         ^^^^^^^^^^^^^^^^^^^
  File "C:\Users\Madhava Sharma\AppData\Local\Programs\Python\Python311\Lib\site-packages\django\urls\resolvers.py", line 715, in url_patterns
    patterns = getattr(self.urlconf_module, "urlpatterns", self.urlconf_module)
                       ^^^^^^^^^^^^^^^^^^^
  File "C:\Users\Madhava Sharma\AppData\Local\Programs\Python\Python311\Lib\site-packages\django\utils\functional.py", line 57, in __get__
    res = instance.__dict__[self.name] = self.func(instance)
                                         ^^^^^^^^^^^^^^^^^^^
  File "C:\Users\Madhava Sharma\AppData\Local\Programs\Python\Python311\Lib\site-packages\django\urls\resolvers.py", line 708, in urlconf_module
    return import_module(self.urlconf_name)
           ^^^^^^^^^^^^^^^^^^^^^^^^^^^^^^^^
  File "C:\Users\Madhava Sharma\AppData\Local\Programs\Python\Python311\Lib\importlib\__init__.py", line 126, in import_module
    return _bootstrap._gcd_import(name[level:], package, level)
           ^^^^^^^^^^^^^^^^^^^^^^^^^^^^^^^^^^^^^^^^^^^^^^^^^^^^
  File "<frozen importlib._bootstrap>", line 1206, in _gcd_import
  File "<frozen importlib._bootstrap>", line 1178, in _find_and_load
  File "<frozen importlib._bootstrap>", line 1149, in _find_and_load_unlocked
  File "<frozen importlib._bootstrap>", line 690, in _load_unlocked
  File "<frozen importlib._bootstrap_external>", line 940, in exec_module
  File "<frozen importlib._bootstrap>", line 241, in _call_with_frames_removed
  File "C:\Users\Madhava Sharma\Desktop\-python\mapp\mapp\urls.py", line 21, in <module>
    path()
TypeError: _path() missing 2 required positional arguments: 'route' and 'view'
C:\Users\Madhava Sharma\Desktop\-python\mapp\mapp\urls.py changed, reloading.
Watching for file changes with StatReloader
Performing system checks...

Exception in thread django-main-thread:
Traceback (most recent call last):
  File "C:\Users\Madhava Sharma\AppData\Local\Programs\Python\Python311\Lib\threading.py", line 1038, in _bootstrap_inner    self.run()
  File "C:\Users\Madhava Sharma\AppData\Local\Programs\Python\Python311\Lib\threading.py", line 975, in run
    self._target(*self._args, **self._kwargs)
  File "C:\Users\Madhava Sharma\AppData\Local\Programs\Python\Python311\Lib\site-packages\django\utils\autoreload.py", line 64, in wrapper
    fn(*args, **kwargs)
  File "C:\Users\Madhava Sharma\AppData\Local\Programs\Python\Python311\Lib\site-packages\django\core\management\commands\runserver.py", line 134, in inner_run
    self.check(display_num_errors=True)
  File "C:\Users\Madhava Sharma\AppData\Local\Programs\Python\Python311\Lib\site-packages\django\core\management\base.py", line 475, in check
    all_issues = checks.run_checks(
                 ^^^^^^^^^^^^^^^^^^
  File "C:\Users\Madhava Sharma\AppData\Local\Programs\Python\Python311\Lib\site-packages\django\core\checks\registry.py", line 88, in run_checks
    new_errors = check(app_configs=app_configs, databases=databases)
                 ^^^^^^^^^^^^^^^^^^^^^^^^^^^^^^^^^^^^^^^^^^^^^^^^^^^
  File "C:\Users\Madhava Sharma\AppData\Local\Programs\Python\Python311\Lib\site-packages\django\core\checks\urls.py", line 42, in check_url_namespaces_unique
    all_namespaces = _load_all_namespaces(resolver)
                     ^^^^^^^^^^^^^^^^^^^^^^^^^^^^^^
  File "C:\Users\Madhava Sharma\AppData\Local\Programs\Python\Python311\Lib\site-packages\django\core\checks\urls.py", line 61, in _load_all_namespaces
    url_patterns = getattr(resolver, "url_patterns", [])
                   ^^^^^^^^^^^^^^^^^^^^^^^^^^^^^^^^^^^^^
  File "C:\Users\Madhava Sharma\AppData\Local\Programs\Python\Python311\Lib\site-packages\django\utils\functional.py", line 57, in __get__
    res = instance.__dict__[self.name] = self.func(instance)
                                         ^^^^^^^^^^^^^^^^^^^
  File "C:\Users\Madhava Sharma\AppData\Local\Programs\Python\Python311\Lib\site-packages\django\urls\resolvers.py", line 715, in url_patterns
    patterns = getattr(self.urlconf_module, "urlpatterns", self.urlconf_module)
                       ^^^^^^^^^^^^^^^^^^^
  File "C:\Users\Madhava Sharma\AppData\Local\Programs\Python\Python311\Lib\site-packages\django\utils\functional.py", line 57, in __get__
    res = instance.__dict__[self.name] = self.func(instance)
                                         ^^^^^^^^^^^^^^^^^^^
  File "C:\Users\Madhava Sharma\AppData\Local\Programs\Python\Python311\Lib\site-packages\django\urls\resolvers.py", line 708, in urlconf_module
    return import_module(self.urlconf_name)
           ^^^^^^^^^^^^^^^^^^^^^^^^^^^^^^^^
  File "C:\Users\Madhava Sharma\AppData\Local\Programs\Python\Python311\Lib\importlib\__init__.py", line 126, in import_module
    return _bootstrap._gcd_import(name[level:], package, level)
           ^^^^^^^^^^^^^^^^^^^^^^^^^^^^^^^^^^^^^^^^^^^^^^^^^^^^
  File "<frozen importlib._bootstrap>", line 1206, in _gcd_import
  File "<frozen importlib._bootstrap>", line 1178, in _find_and_load
  File "<frozen importlib._bootstrap>", line 1149, in _find_and_load_unlocked
  File "<frozen importlib._bootstrap>", line 690, in _load_unlocked
  File "<frozen importlib._bootstrap_external>", line 940, in exec_module
  File "<frozen importlib._bootstrap>", line 241, in _call_with_frames_removed
  File "C:\Users\Madhava Sharma\Desktop\-python\mapp\mapp\urls.py", line 21, in <module>
    path('')
TypeError: _path() missing 1 required positional argument: 'view'
C:\Users\Madhava Sharma\Desktop\-python\mapp\mapp\urls.py changed, reloading.
Watching for file changes with StatReloader
Performing system checks...

Exception in thread django-main-thread:
Traceback (most recent call last):
  File "C:\Users\Madhava Sharma\AppData\Local\Programs\Python\Python311\Lib\threading.py", line 1038, in _bootstrap_inner    self.run()
  File "C:\Users\Madhava Sharma\AppData\Local\Programs\Python\Python311\Lib\threading.py", line 975, in run
    self._target(*self._args, **self._kwargs)
  File "C:\Users\Madhava Sharma\AppData\Local\Programs\Python\Python311\Lib\site-packages\django\utils\autoreload.py", line 64, in wrapper
    fn(*args, **kwargs)
  File "C:\Users\Madhava Sharma\AppData\Local\Programs\Python\Python311\Lib\site-packages\django\core\management\commands\runserver.py", line 134, in inner_run
    self.check(display_num_errors=True)
  File "C:\Users\Madhava Sharma\AppData\Local\Programs\Python\Python311\Lib\site-packages\django\core\management\base.py", line 475, in check
    all_issues = checks.run_checks(
                 ^^^^^^^^^^^^^^^^^^
  File "C:\Users\Madhava Sharma\AppData\Local\Programs\Python\Python311\Lib\site-packages\django\core\checks\registry.py", line 88, in run_checks
    new_errors = check(app_configs=app_configs, databases=databases)
                 ^^^^^^^^^^^^^^^^^^^^^^^^^^^^^^^^^^^^^^^^^^^^^^^^^^^
  File "C:\Users\Madhava Sharma\AppData\Local\Programs\Python\Python311\Lib\site-packages\django\core\checks\urls.py", line 42, in check_url_namespaces_unique
    all_namespaces = _load_all_namespaces(resolver)
                     ^^^^^^^^^^^^^^^^^^^^^^^^^^^^^^
  File "C:\Users\Madhava Sharma\AppData\Local\Programs\Python\Python311\Lib\site-packages\django\core\checks\urls.py", line 61, in _load_all_namespaces
    url_patterns = getattr(resolver, "url_patterns", [])
                   ^^^^^^^^^^^^^^^^^^^^^^^^^^^^^^^^^^^^^
  File "C:\Users\Madhava Sharma\AppData\Local\Programs\Python\Python311\Lib\site-packages\django\utils\functional.py", line 57, in __get__
    res = instance.__dict__[self.name] = self.func(instance)
                                         ^^^^^^^^^^^^^^^^^^^
  File "C:\Users\Madhava Sharma\AppData\Local\Programs\Python\Python311\Lib\site-packages\django\urls\resolvers.py", line 715, in url_patterns
    patterns = getattr(self.urlconf_module, "urlpatterns", self.urlconf_module)
                       ^^^^^^^^^^^^^^^^^^^
  File "C:\Users\Madhava Sharma\AppData\Local\Programs\Python\Python311\Lib\site-packages\django\utils\functional.py", line 57, in __get__
    res = instance.__dict__[self.name] = self.func(instance)
                                         ^^^^^^^^^^^^^^^^^^^
  File "C:\Users\Madhava Sharma\AppData\Local\Programs\Python\Python311\Lib\site-packages\django\urls\resolvers.py", line 708, in urlconf_module
    return import_module(self.urlconf_name)
           ^^^^^^^^^^^^^^^^^^^^^^^^^^^^^^^^
  File "C:\Users\Madhava Sharma\AppData\Local\Programs\Python\Python311\Lib\importlib\__init__.py", line 126, in import_module
    return _bootstrap._gcd_import(name[level:], package, level)
           ^^^^^^^^^^^^^^^^^^^^^^^^^^^^^^^^^^^^^^^^^^^^^^^^^^^^
  File "<frozen importlib._bootstrap>", line 1206, in _gcd_import
  File "<frozen importlib._bootstrap>", line 1178, in _find_and_load
  File "<frozen importlib._bootstrap>", line 1149, in _find_and_load_unlocked
  File "<frozen importlib._bootstrap>", line 690, in _load_unlocked
  File "<frozen importlib._bootstrap_external>", line 940, in exec_module
  File "<frozen importlib._bootstrap>", line 241, in _call_with_frames_removed
  File "C:\Users\Madhava Sharma\Desktop\-python\mapp\mapp\urls.py", line 21, in <module>
    path('employee')
TypeError: _path() missing 1 required positional argument: 'view'
C:\Users\Madhava Sharma\Desktop\-python\mapp\mapp\urls.py changed, reloading.
Watching for file changes with StatReloader
Performing system checks...

Exception in thread django-main-thread:
Traceback (most recent call last):
  File "C:\Users\Madhava Sharma\AppData\Local\Programs\Python\Python311\Lib\threading.py", line 1038, in _bootstrap_inner    self.run()
  File "C:\Users\Madhava Sharma\AppData\Local\Programs\Python\Python311\Lib\threading.py", line 975, in run
    self._target(*self._args, **self._kwargs)
  File "C:\Users\Madhava Sharma\AppData\Local\Programs\Python\Python311\Lib\site-packages\django\utils\autoreload.py", line 64, in wrapper
    fn(*args, **kwargs)
  File "C:\Users\Madhava Sharma\AppData\Local\Programs\Python\Python311\Lib\site-packages\django\core\management\commands\runserver.py", line 134, in inner_run
    self.check(display_num_errors=True)
  File "C:\Users\Madhava Sharma\AppData\Local\Programs\Python\Python311\Lib\site-packages\django\core\management\base.py", line 475, in check
    all_issues = checks.run_checks(
                 ^^^^^^^^^^^^^^^^^^
  File "C:\Users\Madhava Sharma\AppData\Local\Programs\Python\Python311\Lib\site-packages\django\core\checks\registry.py", line 88, in run_checks
    new_errors = check(app_configs=app_configs, databases=databases)
                 ^^^^^^^^^^^^^^^^^^^^^^^^^^^^^^^^^^^^^^^^^^^^^^^^^^^
  File "C:\Users\Madhava Sharma\AppData\Local\Programs\Python\Python311\Lib\site-packages\django\core\checks\urls.py", line 42, in check_url_namespaces_unique
    all_namespaces = _load_all_namespaces(resolver)
                     ^^^^^^^^^^^^^^^^^^^^^^^^^^^^^^
  File "C:\Users\Madhava Sharma\AppData\Local\Programs\Python\Python311\Lib\site-packages\django\core\checks\urls.py", line 61, in _load_all_namespaces
    url_patterns = getattr(resolver, "url_patterns", [])
                   ^^^^^^^^^^^^^^^^^^^^^^^^^^^^^^^^^^^^^
  File "C:\Users\Madhava Sharma\AppData\Local\Programs\Python\Python311\Lib\site-packages\django\utils\functional.py", line 57, in __get__
    res = instance.__dict__[self.name] = self.func(instance)
                                         ^^^^^^^^^^^^^^^^^^^
  File "C:\Users\Madhava Sharma\AppData\Local\Programs\Python\Python311\Lib\site-packages\django\urls\resolvers.py", line 715, in url_patterns
    patterns = getattr(self.urlconf_module, "urlpatterns", self.urlconf_module)
                       ^^^^^^^^^^^^^^^^^^^
  File "C:\Users\Madhava Sharma\AppData\Local\Programs\Python\Python311\Lib\site-packages\django\utils\functional.py", line 57, in __get__
    res = instance.__dict__[self.name] = self.func(instance)
                                         ^^^^^^^^^^^^^^^^^^^
  File "C:\Users\Madhava Sharma\AppData\Local\Programs\Python\Python311\Lib\site-packages\django\urls\resolvers.py", line 708, in urlconf_module
    return import_module(self.urlconf_name)
           ^^^^^^^^^^^^^^^^^^^^^^^^^^^^^^^^
  File "C:\Users\Madhava Sharma\AppData\Local\Programs\Python\Python311\Lib\importlib\__init__.py", line 126, in import_module
    return _bootstrap._gcd_import(name[level:], package, level)
           ^^^^^^^^^^^^^^^^^^^^^^^^^^^^^^^^^^^^^^^^^^^^^^^^^^^^
  File "<frozen importlib._bootstrap>", line 1206, in _gcd_import
  File "<frozen importlib._bootstrap>", line 1178, in _find_and_load
  File "<frozen importlib._bootstrap>", line 1149, in _find_and_load_unlocked
  File "<frozen importlib._bootstrap>", line 690, in _load_unlocked
  File "<frozen importlib._bootstrap_external>", line 940, in exec_module
  File "<frozen importlib._bootstrap>", line 241, in _call_with_frames_removed
  File "C:\Users\Madhava Sharma\Desktop\-python\mapp\mapp\urls.py", line 21, in <module>
    path('employee,')
TypeError: _path() missing 1 required positional argument: 'view'
C:\Users\Madhava Sharma\Desktop\-python\mapp\mapp\urls.py changed, reloading.
Watching for file changes with StatReloader
Performing system checks...

Exception in thread django-main-thread:
Traceback (most recent call last):
  File "C:\Users\Madhava Sharma\AppData\Local\Programs\Python\Python311\Lib\threading.py", line 1038, in _bootstrap_inner    self.run()
  File "C:\Users\Madhava Sharma\AppData\Local\Programs\Python\Python311\Lib\threading.py", line 975, in run
    self._target(*self._args, **self._kwargs)
  File "C:\Users\Madhava Sharma\AppData\Local\Programs\Python\Python311\Lib\site-packages\django\utils\autoreload.py", line 64, in wrapper
    fn(*args, **kwargs)
  File "C:\Users\Madhava Sharma\AppData\Local\Programs\Python\Python311\Lib\site-packages\django\core\management\commands\runserver.py", line 134, in inner_run
    self.check(display_num_errors=True)
  File "C:\Users\Madhava Sharma\AppData\Local\Programs\Python\Python311\Lib\site-packages\django\core\management\base.py", line 475, in check
    all_issues = checks.run_checks(
                 ^^^^^^^^^^^^^^^^^^
  File "C:\Users\Madhava Sharma\AppData\Local\Programs\Python\Python311\Lib\site-packages\django\core\checks\registry.py", line 88, in run_checks
    new_errors = check(app_configs=app_configs, databases=databases)
                 ^^^^^^^^^^^^^^^^^^^^^^^^^^^^^^^^^^^^^^^^^^^^^^^^^^^
  File "C:\Users\Madhava Sharma\AppData\Local\Programs\Python\Python311\Lib\site-packages\django\core\checks\urls.py", line 42, in check_url_namespaces_unique
    all_namespaces = _load_all_namespaces(resolver)
                     ^^^^^^^^^^^^^^^^^^^^^^^^^^^^^^
  File "C:\Users\Madhava Sharma\AppData\Local\Programs\Python\Python311\Lib\site-packages\django\core\checks\urls.py", line 61, in _load_all_namespaces
    url_patterns = getattr(resolver, "url_patterns", [])
                   ^^^^^^^^^^^^^^^^^^^^^^^^^^^^^^^^^^^^^
  File "C:\Users\Madhava Sharma\AppData\Local\Programs\Python\Python311\Lib\site-packages\django\utils\functional.py", line 57, in __get__
    res = instance.__dict__[self.name] = self.func(instance)
                                         ^^^^^^^^^^^^^^^^^^^
  File "C:\Users\Madhava Sharma\AppData\Local\Programs\Python\Python311\Lib\site-packages\django\urls\resolvers.py", line 715, in url_patterns
    patterns = getattr(self.urlconf_module, "urlpatterns", self.urlconf_module)
                       ^^^^^^^^^^^^^^^^^^^
  File "C:\Users\Madhava Sharma\AppData\Local\Programs\Python\Python311\Lib\site-packages\django\utils\functional.py", line 57, in __get__
    res = instance.__dict__[self.name] = self.func(instance)
                                         ^^^^^^^^^^^^^^^^^^^
  File "C:\Users\Madhava Sharma\AppData\Local\Programs\Python\Python311\Lib\site-packages\django\urls\resolvers.py", line 708, in urlconf_module
    return import_module(self.urlconf_name)
           ^^^^^^^^^^^^^^^^^^^^^^^^^^^^^^^^
  File "C:\Users\Madhava Sharma\AppData\Local\Programs\Python\Python311\Lib\importlib\__init__.py", line 126, in import_module
    return _bootstrap._gcd_import(name[level:], package, level)
           ^^^^^^^^^^^^^^^^^^^^^^^^^^^^^^^^^^^^^^^^^^^^^^^^^^^^
  File "<frozen importlib._bootstrap>", line 1206, in _gcd_import
  File "<frozen importlib._bootstrap>", line 1178, in _find_and_load
  File "<frozen importlib._bootstrap>", line 1149, in _find_and_load_unlocked
  File "<frozen importlib._bootstrap>", line 690, in _load_unlocked
  File "<frozen importlib._bootstrap_external>", line 940, in exec_module
  File "<frozen importlib._bootstrap>", line 241, in _call_with_frames_removed
  File "C:\Users\Madhava Sharma\Desktop\-python\mapp\mapp\urls.py", line 21, in <module>
    path('employee')
TypeError: _path() missing 1 required positional argument: 'view'
C:\Users\Madhava Sharma\Desktop\-python\mapp\mapp\urls.py changed, reloading.
Watching for file changes with StatReloader
Performing system checks...

Exception in thread django-main-thread:
Traceback (most recent call last):
  File "C:\Users\Madhava Sharma\AppData\Local\Programs\Python\Python311\Lib\threading.py", line 1038, in _bootstrap_inner    self.run()
  File "C:\Users\Madhava Sharma\AppData\Local\Programs\Python\Python311\Lib\threading.py", line 975, in run
    self._target(*self._args, **self._kwargs)
  File "C:\Users\Madhava Sharma\AppData\Local\Programs\Python\Python311\Lib\site-packages\django\utils\autoreload.py", line 64, in wrapper
    fn(*args, **kwargs)
  File "C:\Users\Madhava Sharma\AppData\Local\Programs\Python\Python311\Lib\site-packages\django\core\management\commands\runserver.py", line 134, in inner_run
    self.check(display_num_errors=True)
  File "C:\Users\Madhava Sharma\AppData\Local\Programs\Python\Python311\Lib\site-packages\django\core\management\base.py", line 475, in check
    all_issues = checks.run_checks(
                 ^^^^^^^^^^^^^^^^^^
  File "C:\Users\Madhava Sharma\AppData\Local\Programs\Python\Python311\Lib\site-packages\django\core\checks\registry.py", line 88, in run_checks
    new_errors = check(app_configs=app_configs, databases=databases)
                 ^^^^^^^^^^^^^^^^^^^^^^^^^^^^^^^^^^^^^^^^^^^^^^^^^^^
  File "C:\Users\Madhava Sharma\AppData\Local\Programs\Python\Python311\Lib\site-packages\django\core\checks\urls.py", line 42, in check_url_namespaces_unique
    all_namespaces = _load_all_namespaces(resolver)
                     ^^^^^^^^^^^^^^^^^^^^^^^^^^^^^^
  File "C:\Users\Madhava Sharma\AppData\Local\Programs\Python\Python311\Lib\site-packages\django\core\checks\urls.py", line 61, in _load_all_namespaces
    url_patterns = getattr(resolver, "url_patterns", [])
                   ^^^^^^^^^^^^^^^^^^^^^^^^^^^^^^^^^^^^^
  File "C:\Users\Madhava Sharma\AppData\Local\Programs\Python\Python311\Lib\site-packages\django\utils\functional.py", line 57, in __get__
    res = instance.__dict__[self.name] = self.func(instance)
                                         ^^^^^^^^^^^^^^^^^^^
  File "C:\Users\Madhava Sharma\AppData\Local\Programs\Python\Python311\Lib\site-packages\django\urls\resolvers.py", line 715, in url_patterns
    patterns = getattr(self.urlconf_module, "urlpatterns", self.urlconf_module)
                       ^^^^^^^^^^^^^^^^^^^
  File "C:\Users\Madhava Sharma\AppData\Local\Programs\Python\Python311\Lib\site-packages\django\utils\functional.py", line 57, in __get__
    res = instance.__dict__[self.name] = self.func(instance)
                                         ^^^^^^^^^^^^^^^^^^^
  File "C:\Users\Madhava Sharma\AppData\Local\Programs\Python\Python311\Lib\site-packages\django\urls\resolvers.py", line 708, in urlconf_module
    return import_module(self.urlconf_name)
           ^^^^^^^^^^^^^^^^^^^^^^^^^^^^^^^^
  File "C:\Users\Madhava Sharma\AppData\Local\Programs\Python\Python311\Lib\importlib\__init__.py", line 126, in import_module
    return _bootstrap._gcd_import(name[level:], package, level)
           ^^^^^^^^^^^^^^^^^^^^^^^^^^^^^^^^^^^^^^^^^^^^^^^^^^^^
  File "<frozen importlib._bootstrap>", line 1206, in _gcd_import
  File "<frozen importlib._bootstrap>", line 1178, in _find_and_load
  File "<frozen importlib._bootstrap>", line 1149, in _find_and_load_unlocked
  File "<frozen importlib._bootstrap>", line 690, in _load_unlocked
  File "<frozen importlib._bootstrap_external>", line 940, in exec_module
  File "<frozen importlib._bootstrap>", line 241, in _call_with_frames_removed
  File "C:\Users\Madhava Sharma\Desktop\-python\mapp\mapp\urls.py", line 21, in <module>
    path('employee',)
TypeError: _path() missing 1 required positional argument: 'view'
C:\Users\Madhava Sharma\Desktop\-python\mapp\mapp\urls.py changed, reloading.
Watching for file changes with StatReloader
Performing system checks...

Exception in thread django-main-thread:
Traceback (most recent call last):
  File "C:\Users\Madhava Sharma\AppData\Local\Programs\Python\Python311\Lib\threading.py", line 1038, in _bootstrap_inner    self.run()
  File "C:\Users\Madhava Sharma\AppData\Local\Programs\Python\Python311\Lib\threading.py", line 975, in run
    self._target(*self._args, **self._kwargs)
  File "C:\Users\Madhava Sharma\AppData\Local\Programs\Python\Python311\Lib\site-packages\django\utils\autoreload.py", line 64, in wrapper
    fn(*args, **kwargs)
  File "C:\Users\Madhava Sharma\AppData\Local\Programs\Python\Python311\Lib\site-packages\django\core\management\commands\runserver.py", line 134, in inner_run
    self.check(display_num_errors=True)
  File "C:\Users\Madhava Sharma\AppData\Local\Programs\Python\Python311\Lib\site-packages\django\core\management\base.py", line 475, in check
    all_issues = checks.run_checks(
                 ^^^^^^^^^^^^^^^^^^
  File "C:\Users\Madhava Sharma\AppData\Local\Programs\Python\Python311\Lib\site-packages\django\core\checks\registry.py", line 88, in run_checks
    new_errors = check(app_configs=app_configs, databases=databases)
                 ^^^^^^^^^^^^^^^^^^^^^^^^^^^^^^^^^^^^^^^^^^^^^^^^^^^
  File "C:\Users\Madhava Sharma\AppData\Local\Programs\Python\Python311\Lib\site-packages\django\core\checks\urls.py", line 42, in check_url_namespaces_unique
    all_namespaces = _load_all_namespaces(resolver)
                     ^^^^^^^^^^^^^^^^^^^^^^^^^^^^^^
  File "C:\Users\Madhava Sharma\AppData\Local\Programs\Python\Python311\Lib\site-packages\django\core\checks\urls.py", line 61, in _load_all_namespaces
    url_patterns = getattr(resolver, "url_patterns", [])
                   ^^^^^^^^^^^^^^^^^^^^^^^^^^^^^^^^^^^^^
  File "C:\Users\Madhava Sharma\AppData\Local\Programs\Python\Python311\Lib\site-packages\django\utils\functional.py", line 57, in __get__
    res = instance.__dict__[self.name] = self.func(instance)
                                         ^^^^^^^^^^^^^^^^^^^
  File "C:\Users\Madhava Sharma\AppData\Local\Programs\Python\Python311\Lib\site-packages\django\urls\resolvers.py", line 715, in url_patterns
    patterns = getattr(self.urlconf_module, "urlpatterns", self.urlconf_module)
                       ^^^^^^^^^^^^^^^^^^^
  File "C:\Users\Madhava Sharma\AppData\Local\Programs\Python\Python311\Lib\site-packages\django\utils\functional.py", line 57, in __get__
    res = instance.__dict__[self.name] = self.func(instance)
                                         ^^^^^^^^^^^^^^^^^^^
  File "C:\Users\Madhava Sharma\AppData\Local\Programs\Python\Python311\Lib\site-packages\django\urls\resolvers.py", line 708, in urlconf_module
    return import_module(self.urlconf_name)
           ^^^^^^^^^^^^^^^^^^^^^^^^^^^^^^^^
  File "C:\Users\Madhava Sharma\AppData\Local\Programs\Python\Python311\Lib\importlib\__init__.py", line 126, in import_module
    return _bootstrap._gcd_import(name[level:], package, level)
           ^^^^^^^^^^^^^^^^^^^^^^^^^^^^^^^^^^^^^^^^^^^^^^^^^^^^
  File "<frozen importlib._bootstrap>", line 1206, in _gcd_import
  File "<frozen importlib._bootstrap>", line 1178, in _find_and_load
  File "<frozen importlib._bootstrap>", line 1149, in _find_and_load_unlocked
  File "<frozen importlib._bootstrap>", line 690, in _load_unlocked
  File "<frozen importlib._bootstrap_external>", line 940, in exec_module
  File "<frozen importlib._bootstrap>", line 241, in _call_with_frames_removed
  File "C:\Users\Madhava Sharma\Desktop\-python\mapp\mapp\urls.py", line 21, in <module>
    path('employee',views)
  File "C:\Users\Madhava Sharma\AppData\Local\Programs\Python\Python311\Lib\site-packages\django\urls\conf.py", line 89, 
in _path
    raise TypeError(
TypeError: view must be a callable or a list/tuple in the case of include().